Workbook

Sheet DocPages
A1: ServiceName | B1: ServiceShortName | C1: Page | D1: SpanPrefix
A2: Account access manager | B2: account-access | C2: list_account-access.html
A3: Alexa for Business | B3: a4b | C3: list_a4b.html
A4: Amazon AI Operations | B4: aiops | C4: list_aiops.html
A5: Amazon API Gateway | B5: execute-api | C5: list_apigatewaymanagementapi.html | D5: list_apigatewaymanagementapi-action-
A6: Amazon API Gateway Management | B6: apigateway | C6: list_apigateway.html
A7: Amazon API Gateway Management V2 | B7: apigateway | C7: list_apigatewayv2.html | D7: list_apigatewayv2-action-
A8: Amazon AppFlow | B8: appflow | C8: list_appflow.html
A9: Amazon AppIntegrations | B9: app-integrations | C9: list_appintegrations.html | D9: list_appintegrations-action-
A10: Amazon Application Recovery Controller - Zonal Shift | B10: arc-zonal-shift | C10: list_arc-zonal-shift.html
A11: Amazon AppStream 2.0 | B11: appstream | C11: list_appstream.html
A12: Amazon ARC Region switch | B12: arc-region-switch | C12: list_arc-region-switch.html
A13: Amazon Athena | B13: athena | C13: list_athena.html
A14: Amazon Aurora DSQL | B14: dsql | C14: list_dsql.html
A15: Amazon Bedrock | B15: bedrock | C15: list_bedrock.html
A16: Amazon Bedrock Agentcore | B16: bedrock-agentcore | C16: list_bedrock-agentcore.html
A17: Amazon Bedrock Powered by AWS Mantle | B17: bedrock-mantle | C17: list_bedrock-mantle.html
A18: Amazon Bedrock Web Search | B18: bedrock-websearch | C18: list_bedrock-websearch.html
A19: Amazon Bio Discovery | B19: researchstudio | C19: list_researchstudio.html
A20: Amazon Braket | B20: braket | C20: list_braket.html
A21: Amazon Chime | B21: chime | C21: list_chime.html
... A26: Amazon CloudWatch | B26: cloudwatch | C26: list_cloudwatch.html
A27: Amazon CloudWatch Application Insights | B27: applicationinsights | C27: list_application-insights.html | D27: list_application-insights-action-
A28: Amazon CloudWatch Application Signals | B28: application-signals | C28: list_application-signals.html
A29: Amazon CloudWatch Application Signals MCP Server | B29: application-signals-mcp | C29: list_application-signals-mcp.html
A30: Amazon CloudWatch Evidently | B30: evidently | C30: list_evidently.html
A31: Amazon CloudWatch Internet Monitor | B31: internetmonitor | C31: list_internetmonitor.html
A32: Amazon CloudWatch Logs | B32: logs | C32: list_logs.html
A33: Amazon CloudWatch Network Synthetic Monitor | B33: networkmonitor | C33: list_networkmonitor.html
A34: Amazon CloudWatch Observability Access Manager | B34: oam | C34: list_oam.html
A35: Amazon CloudWatch Observability Admin Service | B35: observabilityadmin | C35: list_observabilityadmin.html
A36: Amazon CloudWatch Synthetics | B36: synthetics | C36: list_synthetics.html
A37: Amazon CodeCatalyst | B37: codecatalyst | C37: list_codecatalyst.html
A38: Amazon CodeGuru | B38: codeguru | C38: list_codeguru.html
A39: Amazon CodeGuru Profiler | B39: codeguru-profiler | C39: list_codeguruprofiler.html | D39: list_codeguruprofiler-action-
A40: Amazon CodeGuru Reviewer | B40: codeguru-reviewer | C40: list_codeguru-reviewer.html
A41: Amazon CodeGuru Security | B41: codeguru-security | C41: list_codeguru-security.html
A42: Amazon CodeWhisperer | B42: codewhisperer | C42: list_codewhisperer.html
A43: Amazon Cognito Identity | B43: cognito-identity | C43: list_cognito-identity.html
A44: Amazon Cognito Sync | B44: cognito-sync | C44: list_cognito-sync.html
...

Sheet DocPages (DEV)
A1: ServiceName | B1: ServiceShortName | C1: Page | D1: SpanPrefix | E1: Link | F1: ExampleAction
A2: Account access manager | B2: account-access | C2: list_account-access.html
A3: Alexa for Business | B3: a4b | C3: list_a4b.html
A4: Amazon AI Operations | B4: aiops | C4: list_aiops.html
A5: Amazon API Gateway | B5: execute-api | C5: list_apigatewaymanagementapi.html | D5: ="list_" & MID($C5,6,LEN($C5)-10) & "-action-" -> list_apigatewaymanagementapi-action- | E5: =HYPERLINK("https://docs.aws.amazon.com/service-authorization/latest/reference/" & $C5,"link") -> link | F5: =B5 & ":" & MID($H5,3,FIND(CHAR(34),$H5,3)-3) -> execute-api:InvalidateCache | H5: =INDEX('AwsServices-Temp'!$C$2:$C$478,MATCH($A5,'AwsServices-Temp'!$B$2:$B$478,0)) -> ["InvalidateCache","Invoke","ManageConnections"]
A6: Amazon API Gateway Management | B6: apigateway | C6: list_apigateway.html | E6: =HYPERLINK("https://docs.aws.amazon.com/service-authorization/latest/reference/" & $C6,"link") -> link
A7: Amazon API Gateway Management V2 | B7: apigateway | C7: list_apigatewayv2.html | D7: list_apigatewayv2-action- | E7: =HYPERLINK("https://docs.aws.amazon.com/service-authorization/latest/reference/" & $C7,"link") -> link | F7: =B7 & ":" & MID($H7,3,FIND(CHAR(34),$H7,3)-3) -> apigateway:CreatePortal | G7: X | H7: =INDEX('AwsServices-Temp'!$C$2:$C$478,MATCH($A7,'AwsServices-Temp'!$B$2:$B$478,0)) -> ["CreatePortal","CreatePortalProduct","CreateProductPage","CreateProductRestEndpointPage","CreateRoutingRule","DELETE","DeletePortal","DeletePortalProduct","DeletePortalProductSharingPolicy","DeleteProductPage","DeleteProductRestEndpointPage","DeleteRoutingRule","DisablePortal","GET","GetPortal","GetPortalProduct","GetPortalProductSharingPolicy","GetProductPage","GetProductRestEndpointPage","GetRoutingRule","ListPortalProducts","ListPortals","ListProductPages","ListProductRestEndpointPages","ListRoutingRules","PATCH","POST","PUT","PreviewPortal","PublishPortal","PutPortalProductSharingPolicy","UpdatePortal","UpdatePortalProduct","UpdateProductPage","UpdateProductRestEndpointPage","UpdateRoutingRule"]
A8: Amazon AppFlow | B8: appflow | C8: list_appflow.html
A9: Amazon AppIntegrations | B9: app-integrations | C9: list_appintegrations.html | D9: ="list_" & MID($C9,6,LEN($C9)-10) & "-action-" -> list_appintegrations-action- | E9: =HYPERLINK("https://docs.aws.amazon.com/service-authorization/latest/reference/" & $C9,"link") -> link | F9: =B9 & ":" & MID($H9,3,FIND(CHAR(34),$H9,3)-3) -> app-integrations:CreateApplication | H9: =INDEX('AwsServices-Temp'!$C$2:$C$478,MATCH($A9,'AwsServices-Temp'!$B$2:$B$478,0)) -> ["CreateApplication","CreateApplicationAssociation","CreateDataIntegration","CreateDataIntegrationAssociation","CreateDataIntegrationSchedule","CreateEventIntegration","CreateEventIntegrationAssociation","DeleteApplication","DeleteApplicationAssociation","DeleteDataIntegration","DeleteDataIntegrationAssociation","DeleteEventIntegration","DeleteEventIntegrationAssociation","GetApplication","GetDataIntegration","GetDataIntegrationExecution","GetDataIntegrationSchedule","GetEventIntegration","ListApplicationAssociations","ListApplications","ListDataIntegrationAssociations","ListDataIntegrationExecutions","ListDataIntegrationSchedules","ListDataIntegrations","ListEventIntegrationAssociations","ListEventIntegrations","ListTagsForResource","StartDataIntegrationExecution","TagResource","UntagResource","UpdateApplication","UpdateDataIntegration","UpdateDataIntegrationAssociation","UpdateDataIntegrationSchedule","UpdateEventIntegration"]
A10: Amazon Application Recovery Controller - Zonal Shift | B10: arc-zonal-shift | C10: list_arc-zonal-shift.html
A11: Amazon AppStream 2.0 | B11: appstream | C11: list_appstream.html
A12: Amazon ARC Region switch | B12: arc-region-switch | C12: list_arc-region-switch.html
A13: Amazon Athena | B13: athena | C13: list_athena.html
A14: Amazon Aurora DSQL | B14: dsql | C14: list_dsql.html
A15: Amazon Bedrock | B15: bedrock | C15: list_bedrock.html
A16: Amazon Bedrock Agentcore | B16: bedrock-agentcore | C16: list_bedrock-agentcore.html
A17: Amazon Bedrock Powered by AWS Mantle | B17: bedrock-mantle | C17: list_bedrock-mantle.html
A18: Amazon Bedrock Web Search | B18: bedrock-websearch | C18: list_bedrock-websearch.html
A19: Amazon Bio Discovery | B19: researchstudio | C19: list_researchstudio.html
A20: Amazon Braket | B20: braket | C20: list_braket.html
A21: Amazon Chime | B21: chime | C21: list_chime.html
... A26: Amazon CloudWatch | B26: cloudwatch | C26: list_cloudwatch.html
A27: Amazon CloudWatch Application Insights | B27: applicationinsights | C27: list_application-insights.html | D27: ="list_" & MID($C27,6,LEN($C27)-10) & "-action-" -> list_application-insights-action- | E27: =HYPERLINK("https://docs.aws.amazon.com/service-authorization/latest/reference/" & $C27,"link") -> link | F27: =B27 & ":" & MID($H27,3,FIND(CHAR(34),$H27,3)-3) -> applicationinsights:AddWorkload | H27: =INDEX('AwsServices-Temp'!$C$2:$C$478,MATCH($A27,'AwsServices-Temp'!$B$2:$B$478,0)) -> ["AddWorkload","CreateApplication","CreateComponent","CreateLogPattern","DeleteApplication","DeleteComponent","DeleteLogPattern","DescribeApplication","DescribeComponent","DescribeComponentConfiguration","DescribeComponentConfigurationRecommendation","DescribeLogPattern","DescribeObservation","DescribeProblem","DescribeProblemObservations","DescribeWorkload","Link","ListApplications","ListComponents","ListConfigurationHistory","ListLogPatternSets","ListLogPatterns","ListProblems","ListTagsForResource","ListWorkloads","RemoveWorkload","TagResource","UntagResource","UpdateApplication","UpdateComponent","UpdateComponentConfiguration","UpdateLogPattern","UpdateProblem","UpdateWorkload"]
A28: Amazon CloudWatch Application Signals | B28: application-signals | C28: list_application-signals.html
A29: Amazon CloudWatch Application Signals MCP Server | B29: application-signals-mcp | C29: list_application-signals-mcp.html
A30: Amazon CloudWatch Evidently | B30: evidently | C30: list_evidently.html
A31: Amazon CloudWatch Internet Monitor | B31: internetmonitor | C31: list_internetmonitor.html
A32: Amazon CloudWatch Logs | B32: logs | C32: list_logs.html
A33: Amazon CloudWatch Network Synthetic Monitor | B33: networkmonitor | C33: list_networkmonitor.html
A34: Amazon CloudWatch Observability Access Manager | B34: oam | C34: list_oam.html
A35: Amazon CloudWatch Observability Admin Service | B35: observabilityadmin | C35: list_observabilityadmin.html
A36: Amazon CloudWatch Synthetics | B36: synthetics | C36: list_synthetics.html
A37: Amazon CodeCatalyst | B37: codecatalyst | C37: list_codecatalyst.html
A38: Amazon CodeGuru | B38: codeguru | C38: list_codeguru.html
A39: Amazon CodeGuru Profiler | B39: codeguru-profiler | C39: list_codeguruprofiler.html | D39: ="list_" & MID($C39,6,LEN($C39)-10) & "-action-" -> list_codeguruprofiler-action- | E39: =HYPERLINK("https://docs.aws.amazon.com/service-authorization/latest/reference/" & $C39,"link") -> link | F39: =B39 & ":" & MID($H39,3,FIND(CHAR(34),$H39,3)-3) -> codeguru-profiler:AddNotificationChannels | H39: =INDEX('AwsServices-Temp'!$C$2:$C$478,MATCH($A39,'AwsServices-Temp'!$B$2:$B$478,0)) -> ["AddNotificationChannels","BatchGetFrameMetricData","ConfigureAgent","CreateProfilingGroup","DeleteProfilingGroup","DescribeProfilingGroup","GetFindingsReportAccountSummary","GetNotificationConfiguration","GetPolicy","GetProfile","GetRecommendations","ListFindingsReports","ListProfileTimes","ListProfilingGroups","ListTagsForResource","PostAgentProfile","PutPermission","RemoveNotificationChannel","RemovePermission","SubmitFeedback","TagResource","UntagResource","UpdateProfilingGroup"]
A40: Amazon CodeGuru Reviewer | B40: codeguru-reviewer | C40: list_codeguru-reviewer.html
A41: Amazon CodeGuru Security | B41: codeguru-security | C41: list_codeguru-security.html
A42: Amazon CodeWhisperer | B42: codewhisperer | C42: list_codewhisperer.html
A43: Amazon Cognito Identity | B43: cognito-identity | C43: list_cognito-identity.html
A44: Amazon Cognito Sync | B44: cognito-sync | C44: list_cognito-sync.html
...

Sheet Sheet2
A1: list_apigatewaymanagementapi.html
A2: list_appintegrations.html
A3: list_application-insights.html
A4: list_codeguruprofiler.html
A5: list_voice-id.html
A6: list_ec2.html
A7: list_interactive-video-service.html
A8: list_keyspaces.html | G8: list_keyspaces.html
A9: list_kinesisanalyticsv2.html
A10: list_kinesis-video-streams.html
A11: list_lex-v2.html
A12: list_location.html
A13: list_amp.html
A14: list_mwaa.html
A15: list_mturk.html
A16: list_neptunedata.html
A17: list_opensearchserverless.html
A18: list_pinpoint.html
A19: list_pinpoint-email.html | G19: list_pinpoint-email.html
A20: list_q-in-connect.html
A21: list_resourcegroupstaggingapi.html
A22: list_s3outposts.html
A23: list_mailmanager.html | G23: list_mailmanager.html
A24: list_sesv2.html | G24: list_sesv2.html
A25: list_simpledb.html
A26: list_workspaces-thin-client.html
A27: list_backupsearch.html
A28: list_cloudcontrol.html | G28: list_cloudcontrol.html
A29: list_compute-optimizer-automation.html
A30: list_devops-agent.html
A31: list_elb.html | G31: list_elb.html
A32: list_elementalinference.html
A33: list_pinpoint-sms-voice-v2.html
A34: list_accessanalyzer.html
A35: list_iam-identity-center.html
A36: list_sso-oidc.html
A37: list_greengrassv2.html | G37: list_greengrassv2.html
A38: list_iot-jobs-data.html
A39: list_iot-managed-integrations.html
A40: list_launch-wizard.html
...

Sheet AwsServices-Temp
A1: ServiceShortName | B1: ServiceName | C1: Actions | D1: ARNFormat | E1: ARNRegex | F1: conditionKeys | G1: HasResource | H1: DocLink
A2: account-access | B2: Account access manager | C2: ["CreateApplication","CreateEntitlement","DeleteApplication","DeleteEntitlement","GetApplication","GetEntitlement","ListApplications","ListEntitlements","ListTagsForResource","TagResource","UntagResource"] | D2: arn:aws:account-access:${Region}:${Account}:${ResourceType}/${ResourceId} | E2: ^arn:aws:account-access:.+ | F2: ["aws:RequestTag/${TagKey}","aws:ResourceTag/${TagKey}","aws:TagKeys"] | G2: TRUE | H2: https://docs.aws.amazon.com/service-authorization/latest/UserGuide/list_accountaccessmanager.html
A3: a4b | B3: Alexa for Business | C3: ["ApproveSkill","AssociateContactWithAddressBook","AssociateDeviceWithNetworkProfile","AssociateDeviceWithRoom","AssociateSkillGroupWithRoom","AssociateSkillWithSkillGroup","AssociateSkillWithUsers","CompleteRegistration","CreateAddressBook","CreateBusinessReportSchedule","CreateConferenceProvider","CreateContact","CreateGatewayGroup","CreateNetworkProfile","CreateProfile","CreateRoom","CreateSkillGroup","CreateUser","DeleteAddressBook","DeleteBusinessReportSchedule","DeleteConferenceProvider","DeleteContact","DeleteDevice","DeleteDeviceUsageData","DeleteGatewayGroup","DeleteNetworkProfile","DeleteProfile","DeleteRoom","DeleteRoomSkillParameter","DeleteSkillAuthorization","DeleteSkillGroup","DeleteUser","DisassociateContactFromAddressBook","DisassociateDeviceFromRoom","DisassociateSkillFromSkillGroup","DisassociateSkillFromUsers","DisassociateSkillGroupFromRoom","ForgetSmartHomeAppliances","GetAddressBook","GetConferencePreference","GetConferenceProvider","GetContact","GetDevice","GetGateway","GetGatewayGroup","GetInvitationConfiguration","GetNetworkProfile","GetProfile","GetRoom","GetRoomSkillParameter","GetSkillGroup","ListBusinessReportSchedules","ListConferenceProviders","ListDeviceEvents","ListGatewayGroups","ListGateways","ListSkills","ListSkillsStoreCategories","ListSkillsStoreSkillsByCategory","ListSmartHomeAppliances","ListTags","PutConferencePreference","PutDeviceSetupEvents","PutInvitationConfiguration","PutRoomSkillParameter","PutSkillAuthorization","RegisterAVSDevice","RegisterDevice","RejectSkill","ResolveRoom","RevokeInvitation","SearchAddressBooks","SearchContacts","SearchDevices","SearchNetworkProfiles","SearchProfiles","SearchRooms","SearchSkillGroups","SearchUsers","SendAnnouncement","SendInvitation","StartDeviceSync","StartSmartHomeApplianceDiscovery","TagResource","UntagResource","UpdateAddressBook","UpdateBusinessReportSchedule","UpdateConferenceProvider","UpdateContact","UpdateDevice","UpdateGateway","UpdateGatewayGroup","UpdateNetworkProfile","UpdateProfile","UpdateRoom","UpdateSkillGroup"] | D3: arn:aws:a4b:${Region}:${Account}:${ResourceType}/${ResourceId} | E3: ^arn:aws:a4b:.+:.+:.+ | F3: ["a4b:amazonId","a4b:filters_deviceType","aws:RequestTag/${TagKey}","aws:ResourceTag/${TagKey}","aws:TagKeys"] | G3: TRUE | H3: https://docs.aws.amazon.com/service-authorization/latest/UserGuide/list_alexaforbusiness.html
A4: aiops | B4: Amazon AI Operations | C4: ["CreateInvestigation","CreateInvestigationEvent","CreateInvestigationGroup","CreateInvestigationResource","CreateReport","DeleteInvestigation","DeleteInvestigationGroup","DeleteInvestigationGroupPolicy","GenerateReport","GetEphemeralInvestigationResults","GetFact","GetFactVersions","GetInvestigation","GetInvestigationEvent","GetInvestigationGroup","GetInvestigationGroupPolicy","GetInvestigationResource","GetReport","ListFacts","ListInvestigationEvents","ListInvestigationGroups","ListInvestigations","ListReports","ListTagsForResource","PutFact","PutInvestigationGroupPolicy","TagResource","UntagResource","UpdateInvestigation","UpdateInvestigationEvent","UpdateInvestigationGroup","UpdateReport","ValidateInvestigationGroup"] | D4: arn:aws:aiops:${Region}:${Account}:.+ | E4: ^arn:aws:aiops:.+:.+:.+ | F4: ["aws:RequestTag/${TagKey}","aws:ResourceTag/${TagKey}","aws:TagKeys"] | G4: TRUE | H4: https://docs.aws.amazon.com/service-authorization/latest/UserGuide/list_amazonaioperations.html
A5: execute-api | B5: Amazon API Gateway | C5: ["InvalidateCache","Invoke","ManageConnections"] | D5: arn:aws:execute-api:${Region}:${Account}:${ResourcePath} | E5: ^arn:aws:execute-api:.+ | F5: "execute-api:viaDomainArn" | G5: TRUE | H5: https://docs.aws.amazon.com/service-authorization/latest/UserGuide/list_amazonapigateway.html
A6: apigateway | B6: Amazon API Gateway Management | C6: ["AddCertificateToDomain","CreateAccessAssociation","DELETE","GET","PATCH","POST","PUT","RejectAccessAssociation","RemoveCertificateFromDomain","SetWebACL","UpdateDomainNameManagementPolicy","UpdateDomainNamePolicy","UpdateRestApiPolicy"] | D6: arn:aws:apigateway:${Region}::${ApiGatewayResourcePath} | E6: ^arn:aws:apigateway:.+ | F6: ["apigateway:Request/AccessAssociationSource","apigateway:Request/AccessLoggingDestination","apigateway:Request/AccessLoggingFormat","apigateway:Request/ApiKeyRequired","apigateway:Request/ApiName","apigateway:Request/AuthorizerType","apigateway:Request/DisableExecuteApiEndpoint","apigateway:Request/DomainNameArn","apigateway:Request/EndpointType","apigateway:Request/MtlsTrustStoreUri","apigateway:Request/MtlsTrustStoreVersion","apigateway:Request/RouteAuthorizationType","apigateway:Request/RoutingMode","apigateway:Request/SecurityPolicy","apigateway:Request/StageName","apigateway:Resource/AccessLoggingDestination","apigateway:Resource/AccessLoggingFormat","apigateway:Resource/ApiKeyRequired","apigateway:Resource/ApiName","apigateway:Resource/AuthorizerType","apigateway:Resource/DisableExecuteApiEndpoint","apigateway:Resource/EndpointType","apigateway:Resource/MtlsTrustStoreUri","apigateway:Resource/MtlsTrustStoreVersion","apigateway:Resource/RouteAuthorizationType","apigateway:Resource/RoutingMode","apigateway:Resource/SecurityPolicy","aws:RequestTag/${TagKey}","aws:ResourceTag/${TagKey}","aws:TagKeys"] | G6: TRUE | H6: https://docs.aws.amazon.com/service-authorization/latest/UserGuide/list_amazonapigatewaymanagement.html
A7: apigateway | B7: Amazon API Gateway Management V2 | C7: ["CreatePortal","CreatePortalProduct","CreateProductPage","CreateProductRestEndpointPage","CreateRoutingRule","DELETE","DeletePortal","DeletePortalProduct","DeletePortalProductSharingPolicy","DeleteProductPage","DeleteProductRestEndpointPage","DeleteRoutingRule","DisablePortal","GET","GetPortal","GetPortalProduct","GetPortalProductSharingPolicy","GetProductPage","GetProductRestEndpointPage","GetRoutingRule","ListPortalProducts","ListPortals","ListProductPages","ListProductRestEndpointPages","ListRoutingRules","PATCH","POST","PUT","PreviewPortal","PublishPortal","PutPortalProductSharingPolicy","UpdatePortal","UpdatePortalProduct","UpdateProductPage","UpdateProductRestEndpointPage","UpdateRoutingRule"] | D7: arn:aws:apigateway:${Region}::${ApiGatewayResourcePath} | E7: ^arn:aws:apigateway:.+ | F7: ["apigateway:Request/AccessLoggingDestination","apigateway:Request/AccessLoggingFormat","apigateway:Request/ApiKeyRequired","apigateway:Request/ApiName","apigateway:Request/AuthorizerType","apigateway:Request/AuthorizerUri","apigateway:Request/CognitoUserPoolArn","apigateway:Request/ConditionBasePaths","apigateway:Request/DisableExecuteApiEndpoint","apigateway:Request/EndpointType","apigateway:Request/Method","apigateway:Request/MtlsTrustStoreUri","apigateway:Request/MtlsTrustStoreVersion","apigateway:Request/PortalDisplayName","apigateway:Request/PortalDomainName","apigateway:Request/PortalProductDisplayName","apigateway:Request/Priority","apigateway:Request/ProductPageTitle","apigateway:Request/ProductRestEndpointPageEndpointPrefix","apigateway:Request/RestApiId","apigateway:Request/RouteAuthorizationType","apigateway:Request/RoutingMode","apigateway:Request/SecurityPolicy","apigateway:Request/Stage","apigateway:Request/StageName","apigateway:Resource/AccessLoggingDestination","apigateway:Resource/AccessLoggingFormat","apigateway:Resource/ApiKeyRequired","apigateway:Resource/ApiName","apigateway:Resource/AuthorizerType","apigateway:Resource/AuthorizerUri","apigateway:Resource/CognitoUserPoolArn","apigateway:Resource/ConditionBasePaths","apigateway:Resource/DisableExecuteApiEndpoint","apigateway:Resource/EndpointType","apigateway:Resource/Method","apigateway:Resource/MtlsTrustStoreUri","apigateway:Resource/MtlsTrustStoreVersion","apigateway:Resource/PortalDisplayName","apigateway:Resource/PortalDomainName","apigateway:Resource/PortalProductDisplayName","apigateway:Resource/PortalPublishStatus","apigateway:Resource/Priority","apigateway:Resource/ProductPageTitle","apigateway:Resource/ProductRestEndpointPageEndpointPrefix","apigateway:Resource/RestApiId","apigateway:Resource/RouteAuthorizationType","apigateway:Resource/RoutingMode","apigateway:Resource/SecurityPolicy","apigateway:Resource/Stage","aws:RequestTag/${TagKey}","aws:ResourceTag/${TagKey}","aws:TagKeys"] | G7: TRUE | H7: https://docs.aws.amazon.com/service-authorization/latest/UserGuide/list_amazonapigatewaymanagementv2.html
A8: appflow | B8: Amazon AppFlow | C8: ["CancelFlowExecutions","CreateConnectorProfile","CreateFlow","DeleteConnectorProfile","DeleteFlow","DescribeConnector","DescribeConnectorEntity","DescribeConnectorFields","DescribeConnectorProfiles","DescribeConnectors","DescribeFlow","DescribeFlowExecution","DescribeFlowExecutionRecords","DescribeFlows","ListConnectorEntities","ListConnectorFields","ListConnectors","ListFlows","ListTagsForResource","RegisterConnector","ResetConnectorMetadataCache","RunFlow","StartFlow","StopFlow","TagResource","UnRegisterConnector","UntagResource","UpdateConnectorProfile","UpdateConnectorRegistration","UpdateFlow","UseConnectorProfile"] | D8: arn:aws:appflow:${Region}:${Account}:${ResourceType}/${ResourceName} | E8: ^arn:aws:appflow:.+:.+:.+ | F8: ["aws:RequestTag/${TagKey}","aws:ResourceTag/${TagKey}","aws:TagKeys"] | G8: TRUE | H8: https://docs.aws.amazon.com/service-authorization/latest/UserGuide/list_amazonappflow.html
A9: app-integrations | B9: Amazon AppIntegrations | C9: ["CreateApplication","CreateApplicationAssociation","CreateDataIntegration","CreateDataIntegrationAssociation","CreateDataIntegrationSchedule","CreateEventIntegration","CreateEventIntegrationAssociation","DeleteApplication","DeleteApplicationAssociation","DeleteDataIntegration","DeleteDataIntegrationAssociation","DeleteEventIntegration","DeleteEventIntegrationAssociation","GetApplication","GetDataIntegration","GetDataIntegrationExecution","GetDataIntegrationSchedule","GetEventIntegration","ListApplicationAssociations","ListApplications","ListDataIntegrationAssociations","ListDataIntegrationExecutions","ListDataIntegrationSchedules","ListDataIntegrations","ListEventIntegrationAssociations","ListEventIntegrations","ListTagsForResource","StartDataIntegrationExecution","TagResource","UntagResource","UpdateApplication","UpdateDataIntegration","UpdateDataIntegrationAssociation","UpdateDataIntegrationSchedule","UpdateEventIntegration"] | D9: arn:aws:app-integrations:${Region}:${Account}:${ResourceType}/${ResourceName} | E9: ^arn:aws:app-integrations:.+:.+:.+ | F9: ["aws:RequestTag/${TagKey}","aws:ResourceTag/${TagKey}","aws:TagKeys"] | G9: TRUE | H9: https://docs.aws.amazon.com/service-authorization/latest/UserGuide/list_amazonappintegrations.html
A10: arc-zonal-shift | B10: Amazon Application Recovery Controller - Zonal Shift | C10: ["CancelPracticeRun","CancelZonalShift","CreatePracticeRunConfiguration","DeletePracticeRunConfiguration","GetAutoshiftObserverNotificationStatus","GetManagedResource","ListAutoshifts","ListManagedResources","ListZonalShifts","StartPracticeRun","StartZonalShift","UpdateAutoshiftObserverNotificationStatus","UpdatePracticeRunConfiguration","UpdateZonalAutoshiftConfiguration","UpdateZonalShift"] | D10: arn:aws:arc-zonal-shift:${Region}:${Account}:${ResourceType}/${ResourceName} | E10: ^arn:aws:arc-zonal-shift:.+:.+:.+ | F10: ["arc-zonal-shift:ResourceIdentifier","aws:ResourceTag/${TagKey}","elasticloadbalancing:ResourceTag/${TagKey}"] | G10: TRUE | H10: https://docs.aws.amazon.com/service-authorization/latest/UserGuide/list_amazonapplicationrecoverycontroller-zonalshift.html
A11: appstream | B11: Amazon AppStream 2.0 | C11: ["AssociateAppBlockBuilderAppBlock","AssociateApplicationFleet","AssociateApplicationToEntitlement","AssociateFleet","AssociateSoftwareToImageBuilder","BatchAssociateUserStack","BatchDisassociateUserStack","CopyImage","CreateAppBlock","CreateAppBlockBuilder","CreateAppBlockBuilderStreamingURL","CreateApplication","CreateDirectoryConfig","CreateEntitlement","CreateExportImageTask","CreateFleet","CreateImageBuilder","CreateImageBuilderStreamingURL","CreateImportedImage","CreateStack","CreateStreamingURL","CreateThemeForStack","CreateUpdatedImage","CreateUsageReportSubscription","CreateUser","DeleteAppBlock","DeleteAppBlockBuilder","DeleteApplication","DeleteDirectoryConfig","DeleteEntitlement","DeleteFleet","DeleteImage","DeleteImageBuilder","DeleteImagePermissions","DeleteStack","DeleteThemeForStack","DeleteUsageReportSubscription","DeleteUser","DescribeAppBlockBuilderAppBlockAssociations","DescribeAppBlockBuilders","DescribeAppBlocks","DescribeAppLicenseUsage","DescribeApplicationFleetAssociations","DescribeApplications","DescribeDirectoryConfigs","DescribeEntitlements","DescribeFleets","DescribeImageBuilders","DescribeImagePermissions","DescribeImages","DescribeSessions","DescribeSoftwareAssociations","DescribeStacks","DescribeThemeForStack","DescribeUsageReportSubscriptions","DescribeUserStackAssociations","DescribeUsers","DisableUser","DisassociateAppBlockBuilderAppBlock","DisassociateApplicationFleet","DisassociateApplicationFromEntitlement","DisassociateFleet","DisassociateSoftwareFromImageBuilder","EnableUser","ExpireSession","GetExportImageTask","ListAssociatedFleets","ListAssociatedStacks","ListEntitledApplications","ListExportImageTasks","ListTagsForResource","StartAppBlockBuilder","StartFleet","StartImageBuilder","StartSoftwareDeploymentToImageBuilder","StopAppBlockBuilder","StopFleet","StopImageBuilder","Stream","TagResource","UntagResource","UpdateAppBlockBuilder","UpdateApplication","UpdateDirectoryConfig","UpdateEntitlement","UpdateFleet","UpdateImagePermissions","UpdateStack","UpdateThemeForStack"] | D11: arn:aws:appstream:${Region}:${Account}:${ResourceType}/${ResourcePath} | E11: ^arn:aws:appstream:.+ | F11: ["appstream:userId","aws:RequestTag/${TagKey}","aws:ResourceTag/${TagKey}","aws:TagKeys"] | G11: TRUE | H11: https://docs.aws.amazon.com/service-authorization/latest/UserGuide/list_amazonappstream2.0.html
A12: arc-region-switch | B12: Amazon ARC Region switch | C12: ["ApprovePlanExecutionStep","CancelPlanExecution","CreatePlan","DeletePlan","DeleteResourcePolicy","GetPlan","GetPlanEvaluationStatus","GetPlanExecution","GetPlanInRegion","GetResourcePolicy","ListPlanExecutionEvents","ListPlanExecutions","ListPlans","ListPlansInRegion","ListRoute53HealthChecks","ListRoute53HealthChecksInRegion","ListServiceQuotaWarnings","ListTagsForResource","PutResourcePolicy","StartPlanExecution","TagResource","UntagResource","UpdatePlan","UpdatePlanExecution","UpdatePlanExecutionStep"] | D12: arn:aws:arc-region-switch::${Account}:${ResourceType} | E12: ^arn:aws:arc-region-switch::.+:.+ | F12: ["aws:RequestTag/${TagKey}","aws:ResourceTag/${TagKey}","aws:TagKeys"] | G12: TRUE | H12: https://docs.aws.amazon.com/service-authorization/latest/UserGuide/list_amazonarcregionswitch.html
A13: athena | B13: Amazon Athena | C13: ["BatchGetNamedQuery","BatchGetPreparedStatement","BatchGetQueryExecution","CancelCapacityReservation","CancelQueryExecution","CreateCapacityReservation","CreateDataCatalog","CreateNamedQuery","CreateNotebook","CreatePreparedStatement","CreatePresignedNotebookUrl","CreateWorkGroup","DeleteCapacityReservation","DeleteDataCatalog","DeleteNamedQuery","DeleteNotebook","DeletePreparedStatement","DeleteWorkGroup","ExportNotebook","GetCalculationExecution","GetCalculationExecutionCode","GetCalculationExecutionStatus","GetCapacityAssignmentConfiguration","GetCapacityReservation","GetCatalogs","GetDataCatalog","GetDatabase","GetExecutionEngine","GetExecutionEngines","GetNamedQuery","GetNamespace","GetNamespaces","GetNotebookMetadata","GetPreparedStatement","GetQueryExecution","GetQueryExecutions","GetQueryResults","GetQueryResultsStream","GetQueryRuntimeStatistics","GetResourceDashboard","GetSession","GetSessionEndpoint","GetSessionStatus","GetTable","GetTableMetadata","GetTables","GetWorkGroup","ImportNotebook","ListApplicationDPUSizes","ListCalculationExecutions","ListCapacityReservations","ListDataCatalogs","ListDatabases","ListEngineVersions","ListExecutors","ListNamedQueries","ListNotebookMetadata","ListNotebookSessions","ListPreparedStatements","ListQueryExecutions","ListSessions","ListTableMetadata","ListTagsForResource","ListWorkGroups","PutCapacityAssignmentConfiguration","RunQuery","StartCalculationExecution","StartQueryExecution","StartSession","StopCalculationExecution","StopQueryExecution","TagResource","TerminateSession","UntagResource","UpdateCapacityReservation","UpdateDataCatalog","UpdateNamedQuery","UpdateNotebook","UpdateNotebookMetadata","UpdatePreparedStatement","UpdateWorkGroup"] | D13: arn:aws:athena:${Region}:${Account}:${ResourceType}/${ResourcePath} | E13: ^arn:aws:athena:.+ | F13: ["aws:RequestTag/${TagKey}","aws:ResourceTag/${TagKey}","aws:TagKeys"] | G13: TRUE | H13: https://docs.aws.amazon.com/service-authorization/latest/UserGuide/list_amazonathena.html
... A18: bedrock-websearch | B18: Amazon Bedrock Web Search | C18: ["ExternalWebAccess","InvokeFetch","InvokeSearch"] | D18: arn:aws:bedrock-websearch:${Region}:${Account}:${ResourceType}/${ResourceName} | E18: ^arn:aws:bedrock-websearch:.+ | F18: null | G18: TRUE | H18: https://docs.aws.amazon.com/service-authorization/latest/UserGuide/list_amazonbedrockwebsearch.html
A19: researchstudio | B19: Amazon Bio Discovery | C19: ["AssignPrincipal","CreateApplication","DeleteApplication","DeletePrincipal","GetApplication","ListApplications"] | E19: ^arn:${Partition}:researchstudio:.+:.+:.+ | F19: null | G19: FALSE | H19: https://docs.aws.amazon.com/service-authorization/latest/UserGuide/list_amazonbiodiscovery.html
A20: braket | B20: Amazon Braket | C20: ["AcceptUserAgreement","CancelJob","CancelQuantumTask","CreateJob","CreateQuantumTask","CreateSpendingLimit","DeleteSpendingLimit","GetDevice","GetJob","GetQuantumTask","GetServiceLinkedRoleStatus","GetUserAgreementStatus","ListTagsForResource","SearchDevices","SearchJobs","SearchQuantumTasks","SearchSpendingLimits","TagResource","UntagResource","UpdateSpendingLimit"] | D20: arn:aws:braket:${Region}:${Account}:.+ | E20: ^arn:aws:braket:${Region}:${Account}:.+ | F20: ["aws:RequestTag/${TagKey}","aws:ResourceTag/${TagKey}","aws:TagKeys"] | G20: TRUE | H20: https://docs.aws.amazon.com/service-authorization/latest/UserGuide/list_amazonbraket.html
A21: chime | B21: Amazon Chime | C21: ["AcceptDelegate","ActivateUsers","AddDomain","AddOrUpdateGroups","AssociateChannelFlow","AssociatePhoneNumberWithUser","AssociatePhoneNumbersWithVoiceConnector","AssociatePhoneNumbersWithVoiceConnectorGroup","AssociateSigninDelegateGroupsWithAccount","AssociateVoiceConnectorConnect","AuthorizeDirectory","BatchCreateAttendee","BatchCreateChannelMembership","BatchCreateRoomMembership","BatchDeletePhoneNumber","BatchSuspendUser","BatchUnsuspendUser","BatchUpdateAttendeeCapabilitiesExcept","BatchUpdatePhoneNumber","BatchUpdateUser","ChannelFlowCallback","Connect","ConnectDirectory","CreateAccount","CreateApiKey","CreateAppInstance","CreateAppInstanceAdmin","CreateAppInstanceBot","CreateAppInstanceUser","CreateAttendee","CreateBot","CreateCDRBucket","CreateChannel","CreateChannelBan","CreateChannelFlow","CreateChannelMembership","CreateChannelModerator","CreateConnectAnalyticsConnector","CreateConnectCallTransferConnector","CreateMediaCapturePipeline","CreateMediaConcatenationPipeline","CreateMediaInsightsPipeline","CreateMediaInsightsPipelineConfiguration","CreateMediaLiveConnectorPipeline","CreateMediaPipelineKinesisVideoStreamPool","CreateMediaStreamPipeline","CreateMeeting","CreateMeetingDialOut","CreateMeetingWithAttendees","CreatePhoneNumberOrder","CreateProxySession","CreateRoom","CreateRoomMembership","CreateSipMediaApplication","CreateSipMediaApplicationCall","CreateSipRule","CreateUser","CreateVoiceConnector","CreateVoiceConnectorGroup","CreateVoiceProfile","CreateVoiceProfileDomain","DeleteAccount","DeleteAccountOpenIdConfig","DeleteApiKey","DeleteAppInstance","DeleteAppInstanceAdmin","DeleteAppInstanceBot","DeleteAppInstanceStreamingConfigurations","DeleteAppInstanceUser","DeleteAttendee","DeleteCDRBucket","DeleteChannel","DeleteChannelBan","DeleteChannelFlow","DeleteChannelMembership","DeleteChannelMessage","DeleteChannelModerator","DeleteDelegate","DeleteDomain","DeleteEventsConfiguration","DeleteGroups","DeleteMediaCapturePipeline","DeleteMediaInsightsPipelineConfiguration","DeleteMediaPipeline","DeleteMediaPipelineKinesisVideoStreamPool","DeleteMeeting","DeleteMessagingStreamingConfigurations","DeletePhoneNumber","DeleteProxySession","DeleteRoom","DeleteRoomMembership","DeleteSipMediaApplication","DeleteSipRule","DeleteVoiceConnector","DeleteVoiceConnectorEmergencyCallingConfiguration","DeleteVoiceConnectorExternalSystemsConfiguration","DeleteVoiceConnectorGroup","DeleteVoiceConnectorOrigination","DeleteVoiceConnectorProxy","DeleteVoiceConnectorStreamingConfiguration","DeleteVoiceConnectorTermination","DeleteVoiceConnectorTerminationCredentials","DeleteVoiceProfile","DeleteVoiceProfileDomain","DeregisterAppInstanceUserEndpoint","DescribeAppInstance","DescribeAppInstanceAdmin","DescribeAppInstanceBot","DescribeAppInstanceUser","DescribeAppInstanceUserEndpoint","DescribeChannel","DescribeChannelBan","DescribeChannelFlow","DescribeChannelMembership","DescribeChannelMembershipForAppInstanceUser","DescribeChannelModeratedByAppInstanceUser","DescribeChannelModerator","DisassociateChannelFlow","DisassociatePhoneNumberFromUser","DisassociatePhoneNumbersFromVoiceConnector","DisassociatePhoneNumbersFromVoiceConnectorGroup","DisassociateSigninDelegateGroupsFromAccount","DisassociateVoiceConnectorConnect","DisconnectDirectory","GetAccount","GetAccountResource","GetAccountSettings","GetAccountWithOpenIdConfig","GetAppInstanceRetentionSettings","GetAppInstanceStreamingConfigurations","GetAttendee","GetBot","GetCDRBucket","GetChannelMembershipPreferences","GetChannelMessage","GetChannelMessageStatus","GetDomain","GetEventsConfiguration","GetGlobalSettings","GetMediaCapturePipeline","GetMediaInsightsPipelineConfiguration","GetMediaPipeline","GetMediaPipelineKinesisVideoStreamPool","GetMeeting","GetMeetingDetail","GetMessagingSessionEndpoint","GetMessagingStreamingConfigurations","GetPhoneNumber","GetPhoneNumberOrder","GetPhoneNumberSettings","GetProxySession","GetRetentionSettings","GetRoom","GetSipMediaApplication","GetSipMediaApplicationAlexaSkillConfiguration","GetSipMediaApplicationLoggingConfiguration","GetSipRule","GetSpeakerSearchTask","GetTelephonyLimits","GetUser","GetUserActivityReportData","GetUserByEmail","GetUserSettings","GetVoiceConnector","GetVoiceConnectorEmergencyCallingConfiguration","GetVoiceConnectorExternalSystemsConfiguration","GetVoiceConnectorGroup","GetVoiceConnectorLoggingConfiguration","GetVoiceConnectorOrigination","GetVoiceConnectorProxy","GetVoiceConnectorStreamingConfiguration","GetVoiceConnectorTermination","GetVoiceConnectorTerminationHealth","GetVoiceProfile","GetVoiceProfileDomain","GetVoiceToneAnalysisTask","InviteDelegate","InviteUsers","InviteUsersFromProvider","ListAccountUsageReportData","ListAccounts","ListApiKeys","ListAppInstanceAdmins","ListAppInstanceBots","ListAppInstanceUserEndpoints","ListAppInstanceUsers","ListAppInstances","ListAttendeeTags","ListAttendees","ListAvailableVoiceConnectorRegions","ListBots","ListCDRBucket","ListCallingRegions","ListChannelBans","ListChannelFlows","ListChannelMemberships","ListChannelMembershipsForAppInstanceUser","ListChannelMessages","ListChannelModerators","ListChannels","ListChannelsAssociatedWithChannelFlow","ListChannelsModeratedByAppInstanceUser","ListDelegates","ListDirectories","ListDomains","ListGroups","ListMediaCapturePipelines","ListMediaInsightsPipelineConfigurations","ListMediaPipelineKinesisVideoStreamPools","ListMediaPipelines","ListMeetingEvents","ListMeetingTags","ListMeetings","ListMeetingsReportData","ListPhoneNumberOrders","ListPhoneNumbers","ListProxySessions","ListRoomMemberships","ListRooms","ListSipMediaApplications","ListSipRules","ListSubChannels","ListSupportedPhoneNumberCountries","ListTagsForResource","ListUsers","ListVoiceConnectorGroups","ListVoiceConnectorTerminationCredentials","ListVoiceConnectors","ListVoiceProfileDomains","ListVoiceProfiles","LogoutUser","PutAppInstanceRetentionSettings","PutAppInstanceStreamingConfigurations","PutAppInstanceUserExpirationSettings","PutChannelExpirationSettings","PutChannelMembershipPreferences","PutEventsConfiguration","PutMessagingStreamingConfigurations","PutRetentionSettings","PutSipMediaApplicationAlexaSkillConfiguration","PutSipMediaApplicationLoggingConfiguration","PutVoiceConnectorEmergencyCallingConfiguration","PutVoiceConnectorExternalSystemsConfiguration","PutVoiceConnectorLoggingConfiguration","PutVoiceConnectorOrigination","PutVoiceConnectorProxy","PutVoiceConnectorStreamingConfiguration","PutVoiceConnectorTermination","PutVoiceConnectorTerminationCredentials","RedactChannelMessage","RedactConversationMessage","RedactRoomMessage","RegenerateSecurityToken","RegisterAppInstanceUserEndpoint","RenameAccount","RenewDelegate","ResetAccountResource","ResetPersonalPIN","RestorePhoneNumber","RetrieveDataExports","SearchAvailablePhoneNumbers","SearchChannels","SendChannelMessage","StartDataExport","StartMeetingTranscription","StartSpeakerSearchTask","StartVoiceToneAnalysisTask","StopMeetingTranscription","StopSpeakerSearchTask","StopVoiceToneAnalysisTask","SubmitSupportRequest","SuspendUsers","TagAttendee","TagMeeting","TagResource","UnauthorizeDirectory","UntagAttendee","UntagMeeting","UntagResource","UpdateAccount","UpdateAccountOpenIdConfig","UpdateAccountResource","UpdateAccountSettings","UpdateAppInstance","UpdateAppInstanceBot","UpdateAppInstanceUser","UpdateAppInstanceUserEndpoint","UpdateAttendeeCapabilities","UpdateBot","UpdateCDRSettings","UpdateChannel","UpdateChannelFlow","UpdateChannelMessage","UpdateChannelReadMarker","UpdateGlobalSettings","UpdateMediaInsightsPipelineConfiguration","UpdateMediaInsightsPipelineStatus","UpdateMediaPipelineKinesisVideoStreamPool","UpdatePhoneNumber","UpdatePhoneNumberSettings","UpdateProxySession","UpdateRoom","UpdateRoomMembership","UpdateSipMediaApplication","UpdateSipMediaApplicationCall","UpdateSipRule","UpdateSupportedLicenses","UpdateUser","UpdateUserLicenses","UpdateUserSettings","UpdateVoiceConnector","UpdateVoiceConnectorGroup","UpdateVoiceProfile","UpdateVoiceProfileDomain","ValidateAccountResource","ValidateE911Address"] | D21: arn:aws:chime:${Region}:${Account}:${ResourceType}/${ResourceID} | E21: ^arn:aws:chime:.+ | F21: ["aws:RequestTag/${TagKey}","aws:ResourceTag/${TagKey}","aws:TagKeys"] | G21: TRUE | H21: https://docs.aws.amazon.com/service-authorization/latest/UserGuide/list_amazonchime.html
A22: clouddirectory | B22: Amazon Cloud Directory | C22: ["AddFacetToObject","ApplySchema","AttachObject","AttachPolicy","AttachToIndex","AttachTypedLink","BatchRead","BatchWrite","CreateDirectory","CreateFacet","CreateIndex","CreateObject","CreateSchema","CreateTypedLinkFacet","DeleteDirectory","DeleteFacet","DeleteObject","DeleteSchema","DeleteTypedLinkFacet","DetachFromIndex","DetachObject","DetachPolicy","DetachTypedLink","DisableDirectory","EnableDirectory","GetAppliedSchemaVersion","GetDirectory","GetFacet","GetLinkAttributes","GetObjectAttributes","GetObjectInformation","GetSchemaAsJson","GetTypedLinkFacetInformation","ListAppliedSchemaArns","ListAttachedIndices","ListDevelopmentSchemaArns","ListDirectories","ListFacetAttributes","ListFacetNames","ListIncomingTypedLinks","ListIndex","ListManagedSchemaArns","ListObjectAttributes","ListObjectChildren","ListObjectParentPaths","ListObjectParents","ListObjectPolicies","ListOutgoingTypedLinks","ListPolicyAttachments","ListPublishedSchemaArns","ListTagsForResource","ListTypedLinkFacetAttributes","ListTypedLinkFacetNames","LookupPolicy","PublishSchema","PutSchemaFromJson","RemoveFacetFromObject","TagResource","UntagResource","UpdateFacet","UpdateLinkAttributes","UpdateObjectAttributes","UpdateSchema","UpdateTypedLinkFacet","UpgradeAppliedSchema","UpgradePublishedSchema"] | D22: arn:aws:clouddirectory:${Region}:${Account}:${RelativeId} | E22: ^arn:aws:clouddirectory:.+:[0-9]+:(directory|schema)/.+ | F22: null | G22: TRUE | H22: https://docs.aws.amazon.com/service-authorization/latest/UserGuide/list_amazonclouddirectory.html
A23: cloudfront | B23: Amazon CloudFront | C23: ["AllowVendedLogDeliveryForResource","AssociateAlias","AssociateDistributionTenantWebACL","AssociateDistributionWebACL","CopyDistribution","CreateAnycastIpList","CreateCachePolicy","CreateCloudFrontOriginAccessIdentity","CreateConnectionFunction","CreateConnectionGroup","CreateContinuousDeploymentPolicy","CreateDistribution","CreateDistributionTenant","CreateFieldLevelEncryptionConfig","CreateFieldLevelEncryptionProfile","CreateFunction","CreateInvalidation","CreateInvalidationForDistributionTenant","CreateKeyGroup","CreateKeyValueStore","CreateMonitoringSubscription","CreateOriginAccessControl","CreateOriginRequestPolicy","CreatePublicKey","CreateRealtimeLogConfig","CreateResponseHeadersPolicy","CreateSavingsPlan","CreateStreamingDistribution","CreateStreamingDistributionWithTags","CreateTrustStore","CreateVpcOrigin","DeleteAnycastIpList","DeleteCachePolicy","DeleteCloudFrontOriginAccessIdentity","DeleteConnectionFunction","DeleteConnectionGroup","DeleteContinuousDeploymentPolicy","DeleteDistribution","DeleteDistributionTenant","DeleteFieldLevelEncryptionConfig","DeleteFieldLevelEncryptionProfile","DeleteFunction","DeleteKeyGroup","DeleteKeyValueStore","DeleteMonitoringSubscription","DeleteOriginAccessControl","DeleteOriginRequestPolicy","DeletePublicKey","DeleteRealtimeLogConfig","DeleteResourcePolicy","DeleteResponseHeadersPolicy","DeleteStreamingDistribution","DeleteTrustStore","DeleteVpcOrigin","DescribeConnectionFunction","DescribeFunction","DescribeKeyValueStore","DisassociateDistributionTenantWebACL","DisassociateDistributionWebACL","GetAnycastIpList","GetCachePolicy","GetCachePolicyConfig","GetCloudFrontOriginAccessIdentity","GetCloudFrontOriginAccessIdentityConfig","GetConnectionFunction","GetConnectionGroup","GetConnectionGroupByRoutingEndpoint","GetContinuousDeploymentPolicy","GetContinuousDeploymentPolicyConfig","GetDistribution","GetDistributionConfig","GetDistributionTenant","GetDistributionTenantByDomain","GetFieldLevelEncryption","GetFieldLevelEncryptionConfig","GetFieldLevelEncryptionProfile","GetFieldLevelEncryptionProfileConfig","GetFunction","GetInvalidation","GetInvalidationForDistributionTenant","GetKeyGroup","GetKeyGroupConfig","GetManagedCertificateDetails","GetMonitoringSubscription","GetOriginAccessControl","GetOriginAccessControlConfig","GetOriginRequestPolicy","GetOriginRequestPolicyConfig","GetPublicKey","GetPublicKeyConfig","GetRealtimeLogConfig","GetResourcePolicy","GetResponseHeadersPolicy","GetResponseHeadersPolicyConfig","GetSavingsPlan","GetStreamingDistribution","GetStreamingDistributionConfig","GetTrustStore","GetVpcOrigin","ListAnycastIpLists","ListCachePolicies","ListCloudFrontOriginAccessIdentities","ListConflictingAliases","ListConnectionFunctions","ListConnectionGroups","ListContinuousDeploymentPolicies","ListDistributionTenants","ListDistributionTenantsByCustomization","ListDistributions","ListDistributionsByAnycastIpListId","ListDistributionsByCachePolicyId","ListDistributionsByConnectionFunction","ListDistributionsByConnectionMode","ListDistributionsByKeyGroup","ListDistributionsByLambdaFunction","ListDistributionsByOriginRequestPolicyId","ListDistributionsByRealtimeLogConfig","ListDistributionsByResponseHeadersPolicyId","ListDistributionsByTrustStore","ListDistributionsByVpcOriginId","ListDistributionsByWebACLId","ListDomainConflicts","ListFieldLevelEncryptionConfigs","ListFieldLevelEncryptionProfiles","ListFunctions","ListInvalidations","ListInvalidationsForDistributionTenant","ListKeyGroups","ListKeyValueStores","ListOriginAccessControls","ListOriginRequestPolicies","ListPublicKeys","ListRateCards","ListRealtimeLogConfigs","ListResponseHeadersPolicies","ListSavingsPlans","ListStreamingDistributions","ListTagsForResource","ListTrustStores","ListUsages","ListVpcOrigins","PublishConnectionFunction","PublishFunction","PutResourcePolicy","TagResource","TestConnectionFunction","TestFunction","UntagResource","UpdateAnycastIpList","UpdateCachePolicy","UpdateCloudFrontOriginAccessIdentity","UpdateConnectionFunction","UpdateConnectionGroup","UpdateContinuousDeploymentPolicy","UpdateDistribution","UpdateDistributionTenant","UpdateDistributionWithStagingConfig","UpdateDomainAssociation","UpdateFieldLevelEncryptionConfig","UpdateFieldLevelEncryptionProfile","UpdateFunction","UpdateKeyGroup","UpdateKeyValueStore","UpdateOriginAccessControl","UpdateOriginRequestPolicy","UpdatePublicKey","UpdateRealtimeLogConfig","UpdateResponseHeadersPolicy","UpdateSavingsPlan","UpdateStreamingDistribution","UpdateTrustStore","UpdateVpcOrigin","VerifyDnsConfiguration"] | D23: arn:aws:cloudfront:${Region}:${Account}:${ResourceType}/${ResourceId} | E23: ^arn:aws:cloudfront:.+:[0-9]+:.+ | F23: ["aws:RequestTag/${TagKey}","aws:ResourceTag/${TagKey}","aws:TagKeys"] | G23: TRUE | H23: https://docs.aws.amazon.com/service-authorization/latest/UserGuide/list_amazoncloudfront.html
A24: cloudfront-keyvaluestore | B24: Amazon CloudFront KeyValueStore | C24: ["DeleteKey","DescribeKeyValueStore","GetKey","ListKeys","PutKey","UpdateKeys"] | D24: arn:aws:cloudfront:${Region}:${Account}:key-value-store/${ResourceId} | E24: ^arn:aws:cloudfront:.+:[0-9]+:.+ | F24: null | G24: TRUE | H24: https://docs.aws.amazon.com/service-authorization/latest/UserGuide/list_amazoncloudfrontkeyvaluestore.html
A25: cloudsearch | B25: Amazon CloudSearch | C25: ["AddTags","BuildSuggesters","CreateDomain","DefineAnalysisScheme","DefineExpression","DefineIndexField","DefineSuggester","DeleteAnalysisScheme","DeleteDomain","DeleteExpression","DeleteIndexField","DeleteSuggester","DescribeAnalysisSchemes","DescribeAvailabilityOptions","DescribeDomainEndpointOptions","DescribeDomains","DescribeExpressions","DescribeIndexFields","DescribeScalingParameters","DescribeServiceAccessPolicies","DescribeSuggesters","IndexDocuments","ListDomainNames","ListTags","RemoveTags","UpdateAvailabilityOptions","UpdateDomainEndpointOptions","UpdateScalingParameters","UpdateServiceAccessPolicies","document","search","suggest"] | D25: arn:aws:cloudsearch:${Region}:${Account}:${ResourceType}/${ResourceName} | E25: ^arn:aws:cloudsearch:.+:.+:.+ | F25: null | G25: TRUE | H25: https://docs.aws.amazon.com/service-authorization/latest/UserGuide/list_amazoncloudsearch.html
A26: cloudwatch | B26: Amazon CloudWatch | C26: ["AssumeAccessProfile","BatchGetServiceLevelIndicatorReport","BatchGetServiceLevelObjectiveBudgetReport","CallWithBearerToken","CreateAccessGrant","CreateAccessProfile","CreateAlert","CreateDomain","CreateDomainAccessGrantForOrganization","CreateDomainForOrganization","CreateIngestionEndpoint","CreateIntegration","CreateOmniDashboard","CreateOmniThread","CreateOneTimeDeepLinkCode","CreateServiceLevelObjective","CreateSpace","CreateView","DeleteAccessGrant","DeleteAccessProfile","DeleteAlarmMuteRule","DeleteAlarms","DeleteAlert","DeleteAnomalyDetector","DeleteDashboards","DeleteDomain","DeleteDomainAccessGrantForOrganization","DeleteDomainForOrganization","DeleteIngestionEndpoint","DeleteInsightRules","DeleteIntegration","DeleteMetricStream","DeleteOmniDashboard","DeleteOmniThread","DeletePipelineRule","DeleteServiceLevelObjective","DeleteSpace","DeleteView","DescribeAlarmHistory","DescribeAlarms","DescribeAlarmsForMetric","DescribeAnomalyDetectors","DescribeInsightRules","DisableAlarmActions","DisableInsightRules","EnableAlarmActions","EnableInsightRules","EnableTopologyDiscovery","GenerateQuery","GenerateQueryResultsSummary","GetAccessGrant","GetAccessProfile","GetAgentGraph","GetAlarmMuteRule","GetAlert","GetContextGraph","GetDashboard","GetDataset","GetDomain","GetDomainAccessGrantForOrganization","GetDomainForOrganization","GetIngestionEndpoint","GetInsightRuleReport","GetIntegration","GetIntelligenceConfiguration","GetMetricData","GetMetricStatistics","GetMetricStream","GetMetricWidgetImage","GetOTelEnrichment","GetOmniDashboard","GetOmniThread","GetPreferences","GetRecords","GetService","GetServiceData","GetServiceLevelObjective","GetSpace","GetSpaceCredentials","GetSpaceCredentialsForOrganization","GetTelemetryQueryResults","GetTopologyDiscoveryStatus","GetTopologyMap","GetView","InvokeIntegration","Link","ListAccessGrants","ListAccessProfiles","ListAlarmMuteRules","ListAlertContributors","ListAlerts","ListDashboards","ListDomainAccessGrantsForOrganization","ListDomains","ListEntitiesForMetric","ListIngestionEndpoints","ListIntegrations","ListManagedInsightRules","ListMetricStreams","ListMetrics","ListOmniDashboards","ListOmniThreads","ListServiceLevelObjectives","ListServices","ListSpaceAccess","ListSpaces","ListSpacesForOrganization","ListTagsForResource","ListTelemetryFields","ListTelemetryQuerySessions","ListViews","PutAlarmMuteRule","PutAnomalyDetector","PutCompositeAlarm","PutDashboard","PutInsightRule","PutIntelligenceConfiguration","PutLogAlarm","PutManagedInsightRules","PutMetricAlarm","PutMetricData","PutMetricStream","PutPipelineRule","QueryTraces","SearchPrincipals","SetAlarmState","StartMetricStreams","StartOTelEnrichment","StartOmniThreadSession","StartTelemetryQuery","StartTelemetryQuerySession","StopMetricStreams","StopOTelEnrichment","StopTelemetryQuery","StopTelemetryQuerySession","SubmitFeedback","TagResource","UntagResource","UpdateAccessProfile","UpdateAlert","UpdateDomain","UpdateDomainForOrganization","UpdateIngestionEndpoint","UpdateIntegration","UpdateOmniDashboard","UpdateOmniThread","UpdatePreferences","UpdateServiceLevelObjective","UpdateSpace","UpdateView"] | D26: arn:aws:cloudwatch:${Region}:${Account}:${ResourceType}/${ResourcePath} | E26: ^arn:aws:cloudwatch:.+ | F26: ["aws:RequestTag/${TagKey}","aws:ResourceTag/${TagKey}","aws:TagKeys","cloudwatch:AlarmActions","cloudwatch:HasAccessGrant","cloudwatch:namespace","cloudwatch:requestInsightRuleLogGroups","cloudwatch:requestManagedResourceARNs"] | G26: TRUE | H26: https://docs.aws.amazon.com/service-authorization/latest/UserGuide/list_amazoncloudwatch.html
A27: applicationinsights | B27: Amazon CloudWatch Application Insights | C27: ["AddWorkload","CreateApplication","CreateComponent","CreateLogPattern","DeleteApplication","DeleteComponent","DeleteLogPattern","DescribeApplication","DescribeComponent","DescribeComponentConfiguration","DescribeComponentConfigurationRecommendation","DescribeLogPattern","DescribeObservation","DescribeProblem","DescribeProblemObservations","DescribeWorkload","Link","ListApplications","ListComponents","ListConfigurationHistory","ListLogPatternSets","ListLogPatterns","ListProblems","ListTagsForResource","ListWorkloads","RemoveWorkload","TagResource","UntagResource","UpdateApplication","UpdateComponent","UpdateComponentConfiguration","UpdateLogPattern","UpdateProblem","UpdateWorkload"] | F27: ["aws:RequestTag/${TagKey}","aws:ResourceTag/${TagKey}","aws:TagKeys"] | G27: FALSE | H27: https://docs.aws.amazon.com/service-authorization/latest/UserGuide/list_amazoncloudwatchapplicationinsights.html
A28: application-signals | B28: Amazon CloudWatch Application Signals | C28: ["BatchDeleteInstrumentationConfigurations","BatchGetServiceLevelObjectiveBudgetReport","BatchUpdateExclusionWindows","CreateInstrumentationConfiguration","CreateServiceLevelObjective","DeleteGroupingConfiguration","DeleteInstrumentationConfiguration","DeleteServiceLevelObjective","GetInstrumentationConfiguration","GetInstrumentationConfigurationStatus","GetService","GetServiceLevelObjective","Link","ListAuditFindings","ListEntityEvents","ListGroupingAttributeDefinitions","ListInstrumentationConfigurations","ListObservedEntities","ListServiceDependencies","ListServiceDependents","ListServiceLevelObjectiveExclusionWindows","ListServiceLevelObjectives","ListServiceOperations","ListServiceStates","ListServices","ListTagsForResource","PutGroupingConfiguration","ReportInstrumentationConfigurationStatus","StartDiscovery","TagResource","UntagResource","UpdateServiceLevelObjective"] | D28: arn:aws:application-signals:${Region}:${Account}:slo/{ServiceLevelObjectivesName} | E28: ^arn:aws:application-signals:.+:.+:.+ | F28: ["aws:RequestTag/${TagKey}","aws:ResourceTag/${TagKey}","aws:TagKeys"] | G28: TRUE | H28: https://docs.aws.amazon.com/service-authorization/latest/UserGuide/list_amazoncloudwatchapplicationsignals.html
A29: application-signals-mcp | B29: Amazon CloudWatch Application Signals MCP Server | C29: ["CallReadOnlyTool","InvokeMcp"] | D29: arn:aws:application-signals-mcp:${Region}:${Account}:mcp-server/${ResourceId} | E29: ^arn:aws:application-signals-mcp:.+:.+:.+ | F29: "aws:ResourceTag/${TagKey}" | G29: TRUE | H29: https://docs.aws.amazon.com/service-authorization/latest/UserGuide/list_amazoncloudwatchapplicationsignalsmcpserver.html
A30: evidently | B30: Amazon CloudWatch Evidently | C30: ["BatchEvaluateFeature","CreateExperiment","CreateFeature","CreateLaunch","CreateProject","CreateSegment","DeleteExperiment","DeleteFeature","DeleteLaunch","DeleteProject","DeleteSegment","EvaluateFeature","GetExperiment","GetExperimentResults","GetFeature","GetLaunch","GetProject","GetSegment","ListExperiments","ListFeatures","ListLaunches","ListProjects","ListSegmentReferences","ListSegments","ListTagsForResource","PutProjectEvents","StartExperiment","StartLaunch","StopExperiment","StopLaunch","TagResource","TestSegmentPattern","UntagResource","UpdateExperiment","UpdateFeature","UpdateLaunch","UpdateProject","UpdateProjectDataDelivery"] | D30: arn:aws:evidently:${Region}:${Account}:${ResourceType}/${ResourceName} | E30: ^arn:aws:evidently:.+:.+:.+ | F30: ["aws:RequestTag/${TagKey}","aws:ResourceTag/${TagKey}","aws:TagKeys"] | G30: TRUE | H30: https://docs.aws.amazon.com/service-authorization/latest/UserGuide/list_amazoncloudwatchevidently.html
A31: internetmonitor | B31: Amazon CloudWatch Internet Monitor | C31: ["CreateMonitor","DeleteMonitor","GetHealthEvent","GetInternetEvent","GetMonitor","GetQueryResults","GetQueryStatus","Link","ListHealthEvents","ListInternetEvents","ListMonitors","ListTagsForResource","StartQuery","StopQuery","TagResource","UntagResource","UpdateMonitor"] | D31: arn:aws:internetmonitor:${Region}:${Account}:${ResourceType}/${ResourcePath} | E31: ^arn:aws:internetmonitor:.+:.+:.+ | F31: ["aws:RequestTag/${TagKey}","aws:ResourceTag/${TagKey}","aws:TagKeys"] | G31: TRUE | H31: https://docs.aws.amazon.com/service-authorization/latest/UserGuide/list_amazoncloudwatchinternetmonitor.html
A32: logs | B32: Amazon CloudWatch Logs | C32: ["AssociateKmsKey","AssociateSourceToS3TableIntegration","CallWithBearerToken","CancelExportTask","CancelImportTask","CreateDelivery","CreateExportTask","CreateImportTask","CreateLogAnomalyDetector","CreateLogDelivery","CreateLogGroup","CreateLogStream","CreateLookupTable","CreateScheduledQuery","DeleteAccountPolicy","DeleteDataProtectionPolicy","DeleteDelivery","DeleteDeliveryDestination","DeleteDeliveryDestinationPolicy","DeleteDeliverySource","DeleteDestination","DeleteIndexPolicy","DeleteIntegration","DeleteLogAnomalyDetector","DeleteLogDelivery","DeleteLogGroup","DeleteLogStream","DeleteLookupTable","DeleteMetricFilter","DeletePipelineRule","DeleteQueryDefinition","DeleteResourcePolicy","DeleteRetentionPolicy","DeleteScheduledQuery","DeleteSubscriptionFilter","DeleteSyslogConfiguration","DeleteTransformer","DescribeAccountPolicies","DescribeConfigurationTemplates","DescribeDeliveries","DescribeDeliveryDestinations","DescribeDeliverySources","DescribeDestinations","DescribeExportTasks","DescribeFieldIndexes","DescribeImportTaskBatches","DescribeImportTasks","DescribeIndexPolicies","DescribeLogGroups","DescribeLogStreams","DescribeLookupTables","DescribeMetricFilters","DescribeQueries","DescribeQueryDefinitions","DescribeResourcePolicies","DescribeSubscriptionFilters","DisassociateKmsKey","DisassociateSourceFromS3TableIntegration","FilterLogEvents","GetDataProtectionPolicy","GetDelivery","GetDeliveryDestination","GetDeliveryDestinationPolicy","GetDeliverySource","GetIntegration","GetLogAnomalyDetector","GetLogDelivery","GetLogEvents","GetLogFields","GetLogGroupFields","GetLogRecord","GetLookupTable","GetQueryResults","GetScheduledQuery","GetScheduledQueryHistory","GetStorageTierPolicy","GetTransformer","IntegrateWithDataset","IntegrateWithS3Table","Link","ListAggregateLogGroupSummaries","ListAnomalies","ListEntitiesForLogGroup","ListIntegrations","ListLogAnomalyDetectors","ListLogDeliveries","ListLogGroups","ListLogGroupsForEntity","ListLogGroupsForQuery","ListScheduledQueries","ListSourcesForS3TableIntegration","ListSyslogConfigurations","ListTagsForResource","ListTagsLogGroup","ProcessWithPipeline","PutAccountPolicy","PutBearerTokenAuthentication","PutDataProtectionPolicy","PutDeliveryDestination","PutDeliveryDestinationPolicy","PutDeliverySource","PutDestination","PutDestinationPolicy","PutIndexPolicy","PutIntegration","PutLogEvents","PutLogGroupDeletionProtection","PutMetricFilter","PutPipelineRule","PutQueryDefinition","PutResourcePolicy","PutRetentionPolicy","PutStorageTierPolicy","PutSubscriptionFilter","PutSyslogConfiguration","PutTransformer","StartLiveTail","StartQuery","StopLiveTail","StopQuery","TagLogGroup","TagResource","TestMetricFilter","TestTransformer","Unmask","UntagLogGroup","UntagResource","UpdateAnomaly","UpdateDeliveryConfiguration","UpdateLogAnomalyDetector","UpdateLogDelivery","UpdateLookupTable","UpdateScheduledQuery"] | D32: arn:aws:logs:${Region}:${Account}:.+ | E32: ^arn:aws:logs:.+ | F32: ["aws:RequestTag/${TagKey}","aws:ResourceTag/${TagKey}","aws:TagKeys","logs:DeliveryDestinationResourceArn","logs:LogGeneratingResourceArns","logs:data_source_name","logs:data_source_type"] | G32: TRUE | H32: https://docs.aws.amazon.com/service-authorization/latest/UserGuide/list_amazoncloudwatchlogs.html
